[2025-04-11T07:39:16.801+0000] {taskinstance.py:1956} INFO - Dependencies all met for dep_context=non-requeueable deps ti=<TaskInstance: etl_pipeline_modo_prueba.merge_datasets manual__2025-04-11T07:26:59.510100+00:00 [queued]>
[2025-04-11T07:39:16.810+0000] {taskinstance.py:1956} INFO - Dependencies all met for dep_context=requeueable deps ti=<TaskInstance: etl_pipeline_modo_prueba.merge_datasets manual__2025-04-11T07:26:59.510100+00:00 [queued]>
[2025-04-11T07:39:16.810+0000] {taskinstance.py:2170} INFO - Starting attempt 2 of 2
[2025-04-11T07:39:16.853+0000] {taskinstance.py:2191} INFO - Executing <Task(BashOperator): merge_datasets> on 2025-04-11 07:26:59.510100+00:00
[2025-04-11T07:39:16.859+0000] {standard_task_runner.py:60} INFO - Started process 52 to run task
[2025-04-11T07:39:16.862+0000] {standard_task_runner.py:87} INFO - Running: ['***', 'tasks', 'run', 'etl_pipeline_modo_prueba', 'merge_datasets', 'manual__2025-04-11T07:26:59.510100+00:00', '--job-id', '452', '--raw', '--subdir', 'DAGS_FOLDER/etl_workflow.py', '--cfg-path', '/tmp/tmp_a010m6t']
[2025-04-11T07:39:16.863+0000] {standard_task_runner.py:88} INFO - Job 452: Subtask merge_datasets
[2025-04-11T07:39:16.942+0000] {task_command.py:423} INFO - Running <TaskInstance: etl_pipeline_modo_prueba.merge_datasets manual__2025-04-11T07:26:59.510100+00:00 [running]> on host 8159023fde52
[2025-04-11T07:39:17.071+0000] {taskinstance.py:2480} INFO - Exporting env vars: AIRFLOW_CTX_DAG_OWNER='simon' AIRFLOW_CTX_DAG_ID='etl_pipeline_modo_prueba' AIRFLOW_CTX_TASK_ID='merge_datasets' AIRFLOW_CTX_EXECUTION_DATE='2025-04-11T07:26:59.510100+00:00' AIRFLOW_CTX_TRY_NUMBER='2' AIRFLOW_CTX_DAG_RUN_ID='manual__2025-04-11T07:26:59.510100+00:00'
[2025-04-11T07:39:17.072+0000] {subprocess.py:63} INFO - Tmp dir root location: /tmp
[2025-04-11T07:39:17.073+0000] {subprocess.py:75} INFO - Running command: ['/usr/bin/bash', '-c', 'python3 /opt/***/scripts/merge_datasets.py']
[2025-04-11T07:39:17.088+0000] {subprocess.py:86} INFO - Output:
[2025-04-11T07:39:18.834+0000] {subprocess.py:93} INFO - üì• Cargando datasets...
[2025-04-11T07:39:18.834+0000] {subprocess.py:93} INFO - ‚úÖ Carga completada.
[2025-04-11T07:39:18.835+0000] {subprocess.py:93} INFO - üìä Agrupando Spotify...
[2025-04-11T07:39:18.835+0000] {subprocess.py:93} INFO - üèÜ Agrupando Grammy...
[2025-04-11T07:39:18.835+0000] {subprocess.py:93} INFO - üìä Agrupando Last.fm...
[2025-04-11T07:39:18.835+0000] {subprocess.py:93} INFO - üîÄ Uniendo Spotify y Grammy...
[2025-04-11T07:39:18.836+0000] {subprocess.py:93} INFO - üìà Uniendo con Last.fm...
[2025-04-11T07:39:18.836+0000] {subprocess.py:93} INFO - üíæ Guardando dataset final...
[2025-04-11T07:39:18.836+0000] {subprocess.py:93} INFO - Traceback (most recent call last):
[2025-04-11T07:39:18.836+0000] {subprocess.py:93} INFO -   File "/opt/***/scripts/merge_datasets.py", line 94, in <module>
[2025-04-11T07:39:18.836+0000] {subprocess.py:93} INFO -     df_merged.to_parquet("/opt/***/data/output/final_dataset.parquet", index=False)
[2025-04-11T07:39:18.837+0000] {subprocess.py:93} INFO -   File "/home/***/.local/lib/python3.8/site-packages/pandas/core/frame.py", line 2889, in to_parquet
[2025-04-11T07:39:18.837+0000] {subprocess.py:93} INFO -     return to_parquet(
[2025-04-11T07:39:18.837+0000] {subprocess.py:93} INFO -   File "/home/***/.local/lib/python3.8/site-packages/pandas/io/parquet.py", line 411, in to_parquet
[2025-04-11T07:39:18.837+0000] {subprocess.py:93} INFO -     impl.write(
[2025-04-11T07:39:18.838+0000] {subprocess.py:93} INFO -   File "/home/***/.local/lib/python3.8/site-packages/pandas/io/parquet.py", line 161, in write
[2025-04-11T07:39:18.838+0000] {subprocess.py:93} INFO -     path_or_handle, handles, kwargs["filesystem"] = _get_path_or_handle(
[2025-04-11T07:39:18.838+0000] {subprocess.py:93} INFO -   File "/home/***/.local/lib/python3.8/site-packages/pandas/io/parquet.py", line 110, in _get_path_or_handle
[2025-04-11T07:39:18.838+0000] {subprocess.py:93} INFO -     handles = get_handle(
[2025-04-11T07:39:18.838+0000] {subprocess.py:93} INFO -   File "/home/***/.local/lib/python3.8/site-packages/pandas/io/common.py", line 868, in get_handle
[2025-04-11T07:39:18.839+0000] {subprocess.py:93} INFO -     handle = open(handle, ioargs.mode)
[2025-04-11T07:39:18.839+0000] {subprocess.py:93} INFO - PermissionError: [Errno 13] Permission denied: '/opt/***/data/output/final_dataset.parquet'
[2025-04-11T07:39:18.934+0000] {subprocess.py:97} INFO - Command exited with return code 1
[2025-04-11T07:39:18.945+0000] {taskinstance.py:2698} ERROR - Task failed with exception
Traceback (most recent call last):
  File "/home/airflow/.local/lib/python3.8/site-packages/airflow/models/taskinstance.py", line 433, in _execute_task
    result = execute_callable(context=context, **execute_callable_kwargs)
  File "/home/airflow/.local/lib/python3.8/site-packages/airflow/operators/bash.py", line 212, in execute
    raise AirflowException(
airflow.exceptions.AirflowException: Bash command failed. The command returned a non-zero exit code 1.
[2025-04-11T07:39:18.949+0000] {taskinstance.py:1138} INFO - Marking task as FAILED. dag_id=etl_pipeline_modo_prueba, task_id=merge_datasets, execution_date=20250411T072659, start_date=20250411T073916, end_date=20250411T073918
[2025-04-11T07:39:19.002+0000] {standard_task_runner.py:107} ERROR - Failed to execute job 452 for task merge_datasets (Bash command failed. The command returned a non-zero exit code 1.; 52)
[2025-04-11T07:39:19.041+0000] {local_task_job_runner.py:234} INFO - Task exited with return code 1
[2025-04-11T07:39:19.066+0000] {taskinstance.py:3280} INFO - 0 downstream tasks scheduled from follow-on schedule check
