[2025-04-10T18:50:38.487+0000] {taskinstance.py:1956} INFO - Dependencies all met for dep_context=non-requeueable deps ti=<TaskInstance: etl_pipeline_modo_prueba.merge_datasets manual__2025-04-10T18:44:20.185742+00:00 [queued]>
[2025-04-10T18:50:38.497+0000] {taskinstance.py:1956} INFO - Dependencies all met for dep_context=requeueable deps ti=<TaskInstance: etl_pipeline_modo_prueba.merge_datasets manual__2025-04-10T18:44:20.185742+00:00 [queued]>
[2025-04-10T18:50:38.497+0000] {taskinstance.py:2170} INFO - Starting attempt 1 of 2
[2025-04-10T18:50:38.542+0000] {taskinstance.py:2191} INFO - Executing <Task(BashOperator): merge_datasets> on 2025-04-10 18:44:20.185742+00:00
[2025-04-10T18:50:38.547+0000] {standard_task_runner.py:60} INFO - Started process 183 to run task
[2025-04-10T18:50:38.551+0000] {standard_task_runner.py:87} INFO - Running: ['***', 'tasks', 'run', 'etl_pipeline_modo_prueba', 'merge_datasets', 'manual__2025-04-10T18:44:20.185742+00:00', '--job-id', '316', '--raw', '--subdir', 'DAGS_FOLDER/etl_workflow.py', '--cfg-path', '/tmp/tmpsepkuv_c']
[2025-04-10T18:50:38.552+0000] {standard_task_runner.py:88} INFO - Job 316: Subtask merge_datasets
[2025-04-10T18:50:38.642+0000] {task_command.py:423} INFO - Running <TaskInstance: etl_pipeline_modo_prueba.merge_datasets manual__2025-04-10T18:44:20.185742+00:00 [running]> on host e36a3d8afc16
[2025-04-10T18:50:38.794+0000] {taskinstance.py:2480} INFO - Exporting env vars: AIRFLOW_CTX_DAG_OWNER='simon' AIRFLOW_CTX_DAG_ID='etl_pipeline_modo_prueba' AIRFLOW_CTX_TASK_ID='merge_datasets' AIRFLOW_CTX_EXECUTION_DATE='2025-04-10T18:44:20.185742+00:00' AIRFLOW_CTX_TRY_NUMBER='1' AIRFLOW_CTX_DAG_RUN_ID='manual__2025-04-10T18:44:20.185742+00:00'
[2025-04-10T18:50:38.795+0000] {subprocess.py:63} INFO - Tmp dir root location: /tmp
[2025-04-10T18:50:38.796+0000] {subprocess.py:75} INFO - Running command: ['/usr/bin/bash', '-c', 'python3 /opt/***/scripts/merge_datasets.py']
[2025-04-10T18:50:38.807+0000] {subprocess.py:86} INFO - Output:
[2025-04-10T18:50:39.363+0000] {subprocess.py:93} INFO - ‚ùå Error durante el merge: ('cannot mix list and non-list, non-null values', 'Conversion failed for column nominee with type object')
[2025-04-10T18:50:39.456+0000] {subprocess.py:97} INFO - Command exited with return code 0
[2025-04-10T18:50:39.514+0000] {taskinstance.py:1138} INFO - Marking task as SUCCESS. dag_id=etl_pipeline_modo_prueba, task_id=merge_datasets, execution_date=20250410T184420, start_date=20250410T185038, end_date=20250410T185039
[2025-04-10T18:50:39.564+0000] {local_task_job_runner.py:234} INFO - Task exited with return code 0
[2025-04-10T18:50:39.591+0000] {taskinstance.py:3280} INFO - 1 downstream tasks scheduled from follow-on schedule check
