[2025-04-11T03:13:32.407+0000] {taskinstance.py:1956} INFO - Dependencies all met for dep_context=non-requeueable deps ti=<TaskInstance: etl_pipeline_modo_prueba.merge_datasets manual__2025-04-11T03:07:01.537846+00:00 [queued]>
[2025-04-11T03:13:32.417+0000] {taskinstance.py:1956} INFO - Dependencies all met for dep_context=requeueable deps ti=<TaskInstance: etl_pipeline_modo_prueba.merge_datasets manual__2025-04-11T03:07:01.537846+00:00 [queued]>
[2025-04-11T03:13:32.418+0000] {taskinstance.py:2170} INFO - Starting attempt 1 of 2
[2025-04-11T03:13:32.457+0000] {taskinstance.py:2191} INFO - Executing <Task(BashOperator): merge_datasets> on 2025-04-11 03:07:01.537846+00:00
[2025-04-11T03:13:32.464+0000] {standard_task_runner.py:60} INFO - Started process 179 to run task
[2025-04-11T03:13:32.467+0000] {standard_task_runner.py:87} INFO - Running: ['***', 'tasks', 'run', 'etl_pipeline_modo_prueba', 'merge_datasets', 'manual__2025-04-11T03:07:01.537846+00:00', '--job-id', '351', '--raw', '--subdir', 'DAGS_FOLDER/etl_workflow.py', '--cfg-path', '/tmp/tmpj0bawu3r']
[2025-04-11T03:13:32.468+0000] {standard_task_runner.py:88} INFO - Job 351: Subtask merge_datasets
[2025-04-11T03:13:32.540+0000] {task_command.py:423} INFO - Running <TaskInstance: etl_pipeline_modo_prueba.merge_datasets manual__2025-04-11T03:07:01.537846+00:00 [running]> on host 334626cf2d45
[2025-04-11T03:13:32.703+0000] {taskinstance.py:2480} INFO - Exporting env vars: AIRFLOW_CTX_DAG_OWNER='simon' AIRFLOW_CTX_DAG_ID='etl_pipeline_modo_prueba' AIRFLOW_CTX_TASK_ID='merge_datasets' AIRFLOW_CTX_EXECUTION_DATE='2025-04-11T03:07:01.537846+00:00' AIRFLOW_CTX_TRY_NUMBER='1' AIRFLOW_CTX_DAG_RUN_ID='manual__2025-04-11T03:07:01.537846+00:00'
[2025-04-11T03:13:32.704+0000] {subprocess.py:63} INFO - Tmp dir root location: /tmp
[2025-04-11T03:13:32.705+0000] {subprocess.py:75} INFO - Running command: ['/usr/bin/bash', '-c', 'python3 /opt/***/scripts/merge_datasets.py']
[2025-04-11T03:13:32.719+0000] {subprocess.py:86} INFO - Output:
[2025-04-11T03:13:33.189+0000] {subprocess.py:93} INFO - ‚ùå Error durante el merge: "Column(s) ['artist'] do not exist"
[2025-04-11T03:13:33.277+0000] {subprocess.py:97} INFO - Command exited with return code 0
[2025-04-11T03:13:33.351+0000] {taskinstance.py:1138} INFO - Marking task as SUCCESS. dag_id=etl_pipeline_modo_prueba, task_id=merge_datasets, execution_date=20250411T030701, start_date=20250411T031332, end_date=20250411T031333
[2025-04-11T03:13:33.440+0000] {local_task_job_runner.py:234} INFO - Task exited with return code 0
[2025-04-11T03:13:33.501+0000] {taskinstance.py:3280} INFO - 0 downstream tasks scheduled from follow-on schedule check
