[2025-04-09T16:55:01.838+0000] {taskinstance.py:1956} INFO - Dependencies all met for dep_context=non-requeueable deps ti=<TaskInstance: etl_pipeline_modo_prueba.extract_lastfm manual__2025-04-09T15:26:54.720180+00:00 [queued]>
[2025-04-09T16:55:01.854+0000] {taskinstance.py:1956} INFO - Dependencies all met for dep_context=requeueable deps ti=<TaskInstance: etl_pipeline_modo_prueba.extract_lastfm manual__2025-04-09T15:26:54.720180+00:00 [queued]>
[2025-04-09T16:55:01.854+0000] {taskinstance.py:2170} INFO - Starting attempt 2 of 3
[2025-04-09T16:55:01.902+0000] {taskinstance.py:2191} INFO - Executing <Task(BashOperator): extract_lastfm> on 2025-04-09 15:26:54.720180+00:00
[2025-04-09T16:55:01.909+0000] {standard_task_runner.py:60} INFO - Started process 164 to run task
[2025-04-09T16:55:01.913+0000] {standard_task_runner.py:87} INFO - Running: ['***', 'tasks', 'run', 'etl_pipeline_modo_prueba', 'extract_lastfm', 'manual__2025-04-09T15:26:54.720180+00:00', '--job-id', '128', '--raw', '--subdir', 'DAGS_FOLDER/etl_workflow.py', '--cfg-path', '/tmp/tmp0ox6spy6']
[2025-04-09T16:55:01.914+0000] {standard_task_runner.py:88} INFO - Job 128: Subtask extract_lastfm
[2025-04-09T16:55:02.002+0000] {task_command.py:423} INFO - Running <TaskInstance: etl_pipeline_modo_prueba.extract_lastfm manual__2025-04-09T15:26:54.720180+00:00 [running]> on host f6eb19ebacef
[2025-04-09T16:55:02.149+0000] {taskinstance.py:2480} INFO - Exporting env vars: AIRFLOW_CTX_DAG_OWNER='simon' AIRFLOW_CTX_DAG_ID='etl_pipeline_modo_prueba' AIRFLOW_CTX_TASK_ID='extract_lastfm' AIRFLOW_CTX_EXECUTION_DATE='2025-04-09T15:26:54.720180+00:00' AIRFLOW_CTX_TRY_NUMBER='2' AIRFLOW_CTX_DAG_RUN_ID='manual__2025-04-09T15:26:54.720180+00:00'
[2025-04-09T16:55:02.151+0000] {subprocess.py:63} INFO - Tmp dir root location: /tmp
[2025-04-09T16:55:02.153+0000] {subprocess.py:75} INFO - Running command: ['/usr/bin/bash', '-c', 'python3 /opt/***/scripts/extract_lastfm.py']
[2025-04-09T16:55:02.170+0000] {subprocess.py:86} INFO - Output:
[2025-04-09T16:55:12.078+0000] {local_task_job_runner.py:302} WARNING - State of this instance has been externally set to up_for_retry. Terminating instance.
[2025-04-09T16:55:12.080+0000] {process_utils.py:131} INFO - Sending 15 to group 164. PIDs of all processes in the group: [165, 164]
[2025-04-09T16:55:12.081+0000] {process_utils.py:86} INFO - Sending the signal 15 to group 164
[2025-04-09T16:55:12.081+0000] {taskinstance.py:2450} ERROR - Received SIGTERM. Terminating subprocesses.
[2025-04-09T16:55:12.082+0000] {subprocess.py:104} INFO - Sending SIGTERM signal to process group
[2025-04-09T16:55:12.098+0000] {taskinstance.py:2698} ERROR - Task failed with exception
Traceback (most recent call last):
  File "/home/airflow/.local/lib/python3.8/site-packages/airflow/models/taskinstance.py", line 433, in _execute_task
    result = execute_callable(context=context, **execute_callable_kwargs)
  File "/home/airflow/.local/lib/python3.8/site-packages/airflow/operators/bash.py", line 203, in execute
    result = self.subprocess_hook.run_command(
  File "/home/airflow/.local/lib/python3.8/site-packages/airflow/hooks/subprocess.py", line 91, in run_command
    for raw_line in iter(self.sub_process.stdout.readline, b""):
  File "/home/airflow/.local/lib/python3.8/site-packages/airflow/models/taskinstance.py", line 2452, in signal_handler
    raise AirflowException("Task received SIGTERM signal")
airflow.exceptions.AirflowException: Task received SIGTERM signal
[2025-04-09T16:55:12.102+0000] {taskinstance.py:1138} INFO - Marking task as FAILED. dag_id=etl_pipeline_modo_prueba, task_id=extract_lastfm, execution_date=20250409T152654, start_date=20250409T165501, end_date=20250409T165512
[2025-04-09T16:55:12.150+0000] {standard_task_runner.py:107} ERROR - Failed to execute job 128 for task extract_lastfm (Task received SIGTERM signal; 164)
[2025-04-09T16:55:12.175+0000] {process_utils.py:79} INFO - Process psutil.Process(pid=164, status='terminated', exitcode=1, started='16:55:01') (164) terminated with exit code 1
[2025-04-09T16:55:12.176+0000] {process_utils.py:79} INFO - Process psutil.Process(pid=165, status='terminated', started='16:55:01') (165) terminated with exit code None
